Workbook

Sheet Sales
A1: Month | B1: Transaction Number | C1: Product Code | D1: Product Description | E1: Store Cost | F1: Sale Price | G1: Profit | H1: Commision 10% for items less than $50. 20% for items more than $50 | I1: First Name | J1: Last Name | K1: Sale Location
A2: Jan | B2: 1001 | C2: 9822 | D2: Pool Cover | E2: 58.3 | F2: 98.4 | G2: =F2-E2 -> 40.1 | H2: =IF(F2>50,0.2,0.1)*G2 -> 8.02 | I2: Charlie | J2: Barns | K2: NM
A3: Jan | B3: 1002 | C3: 2877 | D3: Net | E3: 11.4 | F3: 16.3 | G3: =F3-E3 -> 4.9 | H3: =IF(F3>50,0.2,0.1)*G3 -> 0.49 | I3: Juan | J3: Hernandez | K3: CA | M3: Practice list:
A4: Jan | B4: 1003 | C4: 2499 | D4: 8 ft Hose | E4: 6.2 | F4: 9.2 | G4: =F4-E4 -> 3 | H4: =IF(F4>50,0.2,0.1)*G4 -> 0.3 | I4: Doug | J4: Smith | K4: AZ | M4: text to columns
A5: Jan | B5: 1004 | C5: 8722 | D5: Water Pump | E5: 344 | F5: 502 | G5: =F5-E5 -> 158 | H5: =IF(F5>50,0.2,0.1)*G5 -> 31.6 | I5: Charlie | J5: Barns | K5: AZ | M5: if
A6: Jan | B6: 1005 | C6: 1109 | D6: Chlorine Test Kit | E6: 3 | F6: 8 | G6: =F6-E6 -> 5 | H6: =IF(F6>50,0.2,0.1)*G6 -> 0.5 | I6: Doug | J6: Smith | K6: AZ | M6: sumif
A7: Jan | B7: 1006 | C7: 9822 | D7: Pool Cover | E7: 58.3 | F7: 98.4 | G7: =F7-E7 -> 40.1 | H7: =IF(F7>50,0.2,0.1)*G7 -> 8.02 | I7: Doug | J7: Smith | K7: AZ | M7: sort
A8: Jan | B8: 1007 | C8: 1109 | D8: Chlorine Test Kit | E8: 3 | F8: 8 | G8: =F8-E8 -> 5 | H8: =IF(F8>50,0.2,0.1)*G8 -> 0.5 | I8: Helen | J8: Johnson | K8: NM | M8: filter
A9: Jan | B9: 1008 | C9: 2877 | D9: Net | E9: 11.4 | F9: 16.3 | G9: =F9-E9 -> 4.9 | H9: =IF(F9>50,0.2,0.1)*G9 -> 0.49 | I9: Doug | J9: Smith | K9: NM | M9: pivot tables
A10: Jan | B10: 1009 | C10: 1109 | D10: Chlorine Test Kit | E10: 3 | F10: 8 | G10: =F10-E10 -> 5 | H10: =IF(F10>50,0.2,0.1)*G10 -> 0.5 | I10: Doug | J10: Smith | K10: AZ | M10: pie chart
A11: Jan | B11: 1010 | C11: 2877 | D11: Net | E11: 11.4 | F11: 16.3 | G11: =F11-E11 -> 4.9 | H11: =IF(F11>50,0.2,0.1)*G11 -> 0.49 | I11: Juan | J11: Hernandez | K11: CO
A12: Jan | B12: 1011 | C12: 2877 | D12: Net | E12: 11.4 | F12: 16.3 | G12: =F12-E12 -> 4.9 | H12: =IF(F12>50,0.2,0.1)*G12 -> 0.49 | I12: Juan | J12: Hernandez | K12: AZ
A13: Jan | B13: 1012 | C13: 4421 | D13: Skimmer | E13: 45 | F13: 87 | G13: =F13-E13 -> 42 | H13: =IF(F13>50,0.2,0.1)*G13 -> 8.4 | I13: Doug | J13: Smith | K13: NM
A14: Jan | B14: 1013 | C14: 9212 | D14: 1 Gal Muratic Acid | E14: 4 | F14: 7 | G14: =F14-E14 -> 3 | H14: =IF(F14>50,0.2,0.1)*G14 -> 0.3 | I14: Helen | J14: Johnson | K14: CO
A15: Jan | B15: 1014 | C15: 8722 | D15: Water Pump | E15: 344 | F15: 502 | G15: =F15-E15 -> 158 | H15: =IF(F15>50,0.2,0.1)*G15 -> 31.6 | I15: Charlie | J15: Barns | K15: CA
A16: Jan | B16: 1015 | C16: 2877 | D16: Net | E16: 11.4 | F16: 16.3 | G16: =F16-E16 -> 4.9 | H16: =IF(F16>50,0.2,0.1)*G16 -> 0.49 | I16: Helen | J16: Johnson | K16: AZ
A17: Jan | B17: 1016 | C17: 2499 | D17: 8 ft Hose | E17: 6.2 | F17: 9.2 | G17: =F17-E17 -> 3 | H17: =IF(F17>50,0.2,0.1)*G17 -> 0.3 | I17: Doug | J17: Smith | K17: CA
A18: Feb | B18: 1017 | C18: 2242 | D18: AutoVac | E18: 60 | F18: 124 | G18: =F18-E18 -> 64 | H18: =IF(F18>50,0.2,0.1)*G18 -> 12.8 | I18: Juan | J18: Hernandez | K18: NM
A19: Feb | B19: 1018 | C19: 1109 | D19: Chlorine Test Kit | E19: 3 | F19: 8 | G19: =F19-E19 -> 5 | H19: =IF(F19>50,0.2,0.1)*G19 -> 0.5 | I19: Doug | J19: Smith | K19: CA
A20: Feb | B20: 1019 | C20: 2499 | D20: 8 ft Hose | E20: 6.2 | F20: 9.2 | G20: =F20-E20 -> 3 | H20: =IF(F20>50,0.2,0.1)*G20 -> 0.3 | I20: Doug | J20: Smith | K20: CO
A21: Feb | B21: 1020 | C21: 2499 | D21: 8 ft Hose | E21: 6.2 | F21: 9.2 | G21: =F21-E21 -> 3 | H21: =IF(F21>50,0.2,0.1)*G21 -> 0.3 | I21: Doug | J21: Smith | K21: NV
A22: Feb | B22: 1021 | C22: 1109 | D22: Chlorine Test Kit | E22: 3 | F22: 8 | G22: =F22-E22 -> 5 | H22: =IF(F22>50,0.2,0.1)*G22 -> 0.5 | I22: Juan | J22: Hernandez | K22: CO
... A172: Dec | B172: 1171 | C172: 4421 | D172: Skimmer | E172: 45 | F172: 87 | G172: =F172-E172 -> 42 | H172: =IF(F172>50,0.2,0.1)*G172 -> 8.4 | I172: Juan | J172: Hernandez | K172: NV
A174: Sum of all items | F174: =SUM(F2:F172) -> 17110.6
A175: Sum of items valued at more than $50 | F175: =SUMIF(F2:F172,">50") -> 16088.4
A176: Sum of items valued at $50 or less | F176: =SUMIF(F2:F172,"<=50") -> 1022.2

Sheet Summary
A1: Summary with SUMIF / COUNTIF — same answers as the pivot tables
A3: Last Name | B3: Sum of Sale Price | C3: Sales
A4: Barns | B4: =SUMIF(Sales!$J$2:$J$172,A4,Sales!$F$2:$F$172) -> 6003.5 | C4: =COUNTIF(Sales!$J$2:$J$172,A4) -> 33
A5: Hernandez | B5: =SUMIF(Sales!$J$2:$J$172,A5,Sales!$F$2:$F$172) -> 2410.7 | C5: =COUNTIF(Sales!$J$2:$J$172,A5) -> 41
A6: Johnson | B6: =SUMIF(Sales!$J$2:$J$172,A6,Sales!$F$2:$F$172) -> 3035.3 | C6: =COUNTIF(Sales!$J$2:$J$172,A6) -> 31
A7: Smith | B7: =SUMIF(Sales!$J$2:$J$172,A7,Sales!$F$2:$F$172) -> 5661.1 | C7: =COUNTIF(Sales!$J$2:$J$172,A7) -> 66
A8: Grand Total | B8: =SUM(B4:B7) -> 17110.6 | C8: =SUM(C4:C7) -> 171
A10: Sale Location | B10: Sum of Sale Price | C10: Sales
A11: AZ | B11: =SUMIF(Sales!$K$2:$K$172,A11,Sales!$F$2:$F$172) -> 5908 | C11: =COUNTIF(Sales!$K$2:$K$172,A11) -> 52
A12: CA | B12: =SUMIF(Sales!$K$2:$K$172,A12,Sales!$F$2:$F$172) -> 3413.6 | C12: =COUNTIF(Sales!$K$2:$K$172,A12) -> 45
A13: CO | B13: =SUMIF(Sales!$K$2:$K$172,A13,Sales!$F$2:$F$172) -> 66 | C13: =COUNTIF(Sales!$K$2:$K$172,A13) -> 6
A14: NM | B14: =SUMIF(Sales!$K$2:$K$172,A14,Sales!$F$2:$F$172) -> 1776.9 | C14: =COUNTIF(Sales!$K$2:$K$172,A14) -> 20
A15: NV | B15: =SUMIF(Sales!$K$2:$K$172,A15,Sales!$F$2:$F$172) -> 4722.5 | C15: =COUNTIF(Sales!$K$2:$K$172,A15) -> 38
A16: UT | B16: =SUMIF(Sales!$K$2:$K$172,A16,Sales!$F$2:$F$172) -> 1223.6 | C16: =COUNTIF(Sales!$K$2:$K$172,A16) -> 10
A17: Grand Total | B17: =SUM(B11:B16) -> 17110.6 | C17: =SUM(C11:C16) -> 171
A19: Product Description | B19: Sum of Sale Price | C19: Sales
A20: 1 Gal Muratic Acid | B20: =SUMIF(Sales!$D$2:$D$172,A20,Sales!$F$2:$F$172) -> 77 | C20: =COUNTIF(Sales!$D$2:$D$172,A20) -> 11
A21: 5 Gal Chlorine | B21: =SUMIF(Sales!$D$2:$D$172,A21,Sales!$F$2:$F$172) -> 693 | C21: =COUNTIF(Sales!$D$2:$D$172,A21) -> 9
A22: 8 ft Hose | B22: =SUMIF(Sales!$D$2:$D$172,A22,Sales!$F$2:$F$172) -> 184 | C22: =COUNTIF(Sales!$D$2:$D$172,A22) -> 20
A23: Algea Killer 8 oz | B23: =SUMIF(Sales!$D$2:$D$172,A23,Sales!$F$2:$F$172) -> 210 | C23: =COUNTIF(Sales!$D$2:$D$172,A23) -> 15
A24: AutoVac | B24: =SUMIF(Sales!$D$2:$D$172,A24,Sales!$F$2:$F$172) -> 1984 | C24: =COUNTIF(Sales!$D$2:$D$172,A24) -> 16
A25: Chlorine Test Kit | B25: =SUMIF(Sales!$D$2:$D$172,A25,Sales!$F$2:$F$172) -> 160 | C25: =COUNTIF(Sales!$D$2:$D$172,A25) -> 20
A26: Net | B26: =SUMIF(Sales!$D$2:$D$172,A26,Sales!$F$2:$F$172) -> 391.2 | C26: =COUNTIF(Sales!$D$2:$D$172,A26) -> 24
A27: Pool Cover | B27: =SUMIF(Sales!$D$2:$D$172,A27,Sales!$F$2:$F$172) -> 2066.4 | C27: =COUNTIF(Sales!$D$2:$D$172,A27) -> 21
A28: Skimmer | B28: =SUMIF(Sales!$D$2:$D$172,A28,Sales!$F$2:$F$172) -> 1305 | C28: =COUNTIF(Sales!$D$2:$D$172,A28) -> 15
A29: Water Pump | B29: =SUMIF(Sales!$D$2:$D$172,A29,Sales!$F$2:$F$172) -> 10040 | C29: =COUNTIF(Sales!$D$2:$D$172,A29) -> 20
A30: Grand Total | B30: =SUM(B20:B29) -> 17110.6 | C30: =SUM(C20:C29) -> 171
A32: Month | B32: Sum of Sale Price | C32: Sales
A33: Jan | B33: =SUMIF(Sales!$A$2:$A$172,A33,Sales!$F$2:$F$172) -> 1418.7 | C33: =COUNTIF(Sales!$A$2:$A$172,A33) -> 16
A34: Feb | B34: =SUMIF(Sales!$A$2:$A$172,A34,Sales!$F$2:$F$172) -> 971.2 | C34: =COUNTIF(Sales!$A$2:$A$172,A34) -> 18
A35: Mar | B35: =SUMIF(Sales!$A$2:$A$172,A35,Sales!$F$2:$F$172) -> 1875.4 | C35: =COUNTIF(Sales!$A$2:$A$172,A35) -> 14
A36: April | B36: =SUMIF(Sales!$A$2:$A$172,A36,Sales!$F$2:$F$172) -> 510.7 | C36: =COUNTIF(Sales!$A$2:$A$172,A36) -> 12
A37: May | B37: =SUMIF(Sales!$A$2:$A$172,A37,Sales!$F$2:$F$172) -> 347.4 | C37: =COUNTIF(Sales!$A$2:$A$172,A37) -> 18
A38: June | B38: =SUMIF(Sales!$A$2:$A$172,A38,Sales!$F$2:$F$172) -> 409.5 | C38: =COUNTIF(Sales!$A$2:$A$172,A38) -> 20
A39: July | B39: =SUMIF(Sales!$A$2:$A$172,A39,Sales!$F$2:$F$172) -> 3992.3 | C39: =COUNTIF(Sales!$A$2:$A$172,A39) -> 26
A40: Aug | B40: =SUMIF(Sales!$A$2:$A$172,A40,Sales!$F$2:$F$172) -> 2513.6 | C40: =COUNTIF(Sales!$A$2:$A$172,A40) -> 17
A41: Sept | B41: =SUMIF(Sales!$A$2:$A$172,A41,Sales!$F$2:$F$172) -> 1542.8 | C41: =COUNTIF(Sales!$A$2:$A$172,A41) -> 8
A42: Oct | B42: =SUMIF(Sales!$A$2:$A$172,A42,Sales!$F$2:$F$172) -> 1153.4 | C42: =COUNTIF(Sales!$A$2:$A$172,A42) -> 8
A43: Nov | B43: =SUMIF(Sales!$A$2:$A$172,A43,Sales!$F$2:$F$172) -> 1601.2 | C43: =COUNTIF(Sales!$A$2:$A$172,A43) -> 10
A44: Dec | B44: =SUMIF(Sales!$A$2:$A$172,A44,Sales!$F$2:$F$172) -> 774.4 | C44: =COUNTIF(Sales!$A$2:$A$172,A44) -> 4
...

Sheet Text to Columns
A1: Practice: select A3:A10, then Data → Text to Columns → Delimited → Space. Answers in E:F use formulas.
A2: Full Name | B2: First (you) | C2: Last (you) | E2: First (answer) | F2: Last (answer)
A3: Charlie Barns | E3: =LEFT(A3,FIND(" ",A3)-1) -> Charlie | F3: =MID(A3,FIND(" ",A3)+1,50) -> Barns
A4: Juan Hernandez | E4: =LEFT(A4,FIND(" ",A4)-1) -> Juan | F4: =MID(A4,FIND(" ",A4)+1,50) -> Hernandez
A5: Doug Smith | E5: =LEFT(A5,FIND(" ",A5)-1) -> Doug | F5: =MID(A5,FIND(" ",A5)+1,50) -> Smith
A6: Helen Johnson | E6: =LEFT(A6,FIND(" ",A6)-1) -> Helen | F6: =MID(A6,FIND(" ",A6)+1,50) -> Johnson
A7: Charlie Barns | E7: =LEFT(A7,FIND(" ",A7)-1) -> Charlie | F7: =MID(A7,FIND(" ",A7)+1,50) -> Barns
A8: Juan Hernandez | E8: =LEFT(A8,FIND(" ",A8)-1) -> Juan | F8: =MID(A8,FIND(" ",A8)+1,50) -> Hernandez
A9: Doug Smith | E9: =LEFT(A9,FIND(" ",A9)-1) -> Doug | F9: =MID(A9,FIND(" ",A9)+1,50) -> Smith
A10: Helen Johnson | E10: =LEFT(A10,FIND(" ",A10)-1) -> Helen | F10: =MID(A10,FIND(" ",A10)+1,50) -> Johnson
